[2023-07-16T01:03:35.790+0000] {taskinstance.py:1103} INFO - Dependencies all met for dep_context=non-requeueable deps ti=<TaskInstance: main_dag.tsk2 scheduled__2023-05-08T00:00:00+00:00 [queued]>
[2023-07-16T01:03:35.815+0000] {taskinstance.py:1103} INFO - Dependencies all met for dep_context=requeueable deps ti=<TaskInstance: main_dag.tsk2 scheduled__2023-05-08T00:00:00+00:00 [queued]>
[2023-07-16T01:03:35.815+0000] {taskinstance.py:1308} INFO - Starting attempt 1 of 1
[2023-07-16T01:03:35.847+0000] {taskinstance.py:1327} INFO - Executing <Task(PythonOperator): tsk2> on 2023-05-08 00:00:00+00:00
[2023-07-16T01:03:35.858+0000] {standard_task_runner.py:57} INFO - Started process 1232 to run task
[2023-07-16T01:03:35.866+0000] {standard_task_runner.py:84} INFO - Running: ['***', 'tasks', 'run', 'main_dag', 'tsk2', 'scheduled__2023-05-08T00:00:00+00:00', '--job-id', '277', '--raw', '--subdir', 'DAGS_FOLDER/main_dag.py', '--cfg-path', '/tmp/tmp6a95w1at']
[2023-07-16T01:03:35.869+0000] {standard_task_runner.py:85} INFO - Job 277: Subtask tsk2
[2023-07-16T01:03:35.961+0000] {task_command.py:410} INFO - Running <TaskInstance: main_dag.tsk2 scheduled__2023-05-08T00:00:00+00:00 [running]> on host 3be1cdcf9db5
[2023-07-16T01:03:36.173+0000] {taskinstance.py:1547} INFO - Exporting env vars: AIRFLOW_CTX_DAG_OWNER='***' AIRFLOW_CTX_DAG_ID='main_dag' AIRFLOW_CTX_TASK_ID='tsk2' AIRFLOW_CTX_EXECUTION_DATE='2023-05-08T00:00:00+00:00' AIRFLOW_CTX_TRY_NUMBER='1' AIRFLOW_CTX_DAG_RUN_ID='scheduled__2023-05-08T00:00:00+00:00'
[2023-07-16T01:03:39.079+0000] {logging_mixin.py:150} WARNING - /home/***/.local/lib/python3.7/site-packages/wikipedia/wikipedia.py:389 GuessedAtParserWarning: No parser was explicitly specified, so I'm using the best available HTML parser for this system ("lxml"). This usually isn't a problem, but if you run this code on another system, or in a different virtual environment, it may use a different parser and behave differently.

The code that caused this warning is on line 389 of the file /home/***/.local/lib/python3.7/site-packages/wikipedia/wikipedia.py. To get rid of this warning, pass the additional argument 'features="lxml"' to the BeautifulSoup constructor.
[2023-07-16T01:03:39.087+0000] {logging_mixin.py:150} INFO - Could not load Python
[2023-07-16T01:03:39.087+0000] {taskinstance.py:1824} ERROR - Task failed with exception
Traceback (most recent call last):
  File "/opt/airflow/dags/main_dag.py", line 57, in get_data
    wiki = wikipedia.page(page)
  File "/home/airflow/.local/lib/python3.7/site-packages/wikipedia/wikipedia.py", line 276, in page
    return WikipediaPage(title, redirect=redirect, preload=preload)
  File "/home/airflow/.local/lib/python3.7/site-packages/wikipedia/wikipedia.py", line 299, in __init__
    self.__load(redirect=redirect, preload=preload)
  File "/home/airflow/.local/lib/python3.7/site-packages/wikipedia/wikipedia.py", line 393, in __load
    raise DisambiguationError(getattr(self, 'title', page['title']), may_refer_to)
wikipedia.exceptions.DisambiguationError: "Python" may refer to: 
Pythonidae
Python (genus)
Python (mythology)
Python (programming language)
CMU Common Lisp
PERQ 3
Python of Aenus
Python (painter)
Python of Byzantium
Python of Catana
Python Anghelo
Python (Efteling)
Python (Busch Gardens Tampa Bay)
Python (Coney Island, Cincinnati, Ohio)
Python (automobile maker)
Python (Ford prototype)
Python (missile)
Python (nuclear primary)
Colt Python
Python (codename)
Python (film)
Monty Python
Python (Monty) Pictures
Timon of Phlius
Pyton
Pithon

During handling of the above exception, another exception occurred:

Traceback (most recent call last):
  File "/home/airflow/.local/lib/python3.7/site-packages/airflow/operators/python.py", line 181, in execute
    return_value = self.execute_callable()
  File "/home/airflow/.local/lib/python3.7/site-packages/airflow/operators/python.py", line 198, in execute_callable
    return self.python_callable(*self.op_args, **self.op_kwargs)
  File "/opt/airflow/dags/main_dag.py", line 61, in get_data
    layer, page = todo_lst[0]
IndexError: list index out of range
[2023-07-16T01:03:39.096+0000] {taskinstance.py:1350} INFO - Marking task as FAILED. dag_id=main_dag, task_id=tsk2, execution_date=20230508T000000, start_date=20230716T010335, end_date=20230716T010339
[2023-07-16T01:03:39.109+0000] {standard_task_runner.py:109} ERROR - Failed to execute job 277 for task tsk2 (list index out of range; 1232)
[2023-07-16T01:03:39.149+0000] {local_task_job_runner.py:225} INFO - Task exited with return code 1
[2023-07-16T01:03:39.245+0000] {taskinstance.py:2653} INFO - 0 downstream tasks scheduled from follow-on schedule check
