[2023-07-16T01:03:47.110+0000] {taskinstance.py:1103} INFO - Dependencies all met for dep_context=non-requeueable deps ti=<TaskInstance: main_dag.tsk2 scheduled__2023-06-02T00:00:00+00:00 [queued]>
[2023-07-16T01:03:47.136+0000] {taskinstance.py:1103} INFO - Dependencies all met for dep_context=requeueable deps ti=<TaskInstance: main_dag.tsk2 scheduled__2023-06-02T00:00:00+00:00 [queued]>
[2023-07-16T01:03:47.136+0000] {taskinstance.py:1308} INFO - Starting attempt 1 of 1
[2023-07-16T01:03:47.162+0000] {taskinstance.py:1327} INFO - Executing <Task(PythonOperator): tsk2> on 2023-06-02 00:00:00+00:00
[2023-07-16T01:03:47.169+0000] {standard_task_runner.py:57} INFO - Started process 1334 to run task
[2023-07-16T01:03:47.173+0000] {standard_task_runner.py:84} INFO - Running: ['***', 'tasks', 'run', 'main_dag', 'tsk2', 'scheduled__2023-06-02T00:00:00+00:00', '--job-id', '320', '--raw', '--subdir', 'DAGS_FOLDER/main_dag.py', '--cfg-path', '/tmp/tmpufwf7qzx']
[2023-07-16T01:03:47.175+0000] {standard_task_runner.py:85} INFO - Job 320: Subtask tsk2
[2023-07-16T01:03:47.244+0000] {task_command.py:410} INFO - Running <TaskInstance: main_dag.tsk2 scheduled__2023-06-02T00:00:00+00:00 [running]> on host 3be1cdcf9db5
[2023-07-16T01:03:47.397+0000] {taskinstance.py:1547} INFO - Exporting env vars: AIRFLOW_CTX_DAG_OWNER='***' AIRFLOW_CTX_DAG_ID='main_dag' AIRFLOW_CTX_TASK_ID='tsk2' AIRFLOW_CTX_EXECUTION_DATE='2023-06-02T00:00:00+00:00' AIRFLOW_CTX_TRY_NUMBER='1' AIRFLOW_CTX_DAG_RUN_ID='scheduled__2023-06-02T00:00:00+00:00'
[2023-07-16T01:03:47.439+0000] {taskinstance.py:1824} ERROR - Task failed with exception
Traceback (most recent call last):
  File "/home/airflow/.local/lib/python3.7/site-packages/airflow/operators/python.py", line 181, in execute
    return_value = self.execute_callable()
  File "/home/airflow/.local/lib/python3.7/site-packages/airflow/operators/python.py", line 198, in execute_callable
    return self.python_callable(*self.op_args, **self.op_kwargs)
  File "/opt/airflow/dags/main_dag.py", line 42, in get_data
    todo_set = set(SEED)
TypeError: 'NoneType' object is not iterable
[2023-07-16T01:03:47.453+0000] {taskinstance.py:1350} INFO - Marking task as FAILED. dag_id=main_dag, task_id=tsk2, execution_date=20230602T000000, start_date=20230716T010347, end_date=20230716T010347
[2023-07-16T01:03:47.471+0000] {standard_task_runner.py:109} ERROR - Failed to execute job 320 for task tsk2 ('NoneType' object is not iterable; 1334)
[2023-07-16T01:03:47.515+0000] {local_task_job_runner.py:225} INFO - Task exited with return code 1
[2023-07-16T01:03:47.540+0000] {taskinstance.py:2653} INFO - 0 downstream tasks scheduled from follow-on schedule check
