[2023-07-16T04:24:51.159+0000] {taskinstance.py:1103} INFO - Dependencies all met for dep_context=non-requeueable deps ti=<TaskInstance: main_dag.preprocess_data manual__2023-07-16T04:24:41.720035+00:00 [queued]>
[2023-07-16T04:24:51.169+0000] {taskinstance.py:1103} INFO - Dependencies all met for dep_context=requeueable deps ti=<TaskInstance: main_dag.preprocess_data manual__2023-07-16T04:24:41.720035+00:00 [queued]>
[2023-07-16T04:24:51.170+0000] {taskinstance.py:1308} INFO - Starting attempt 1 of 1
[2023-07-16T04:24:51.185+0000] {taskinstance.py:1327} INFO - Executing <Task(PythonOperator): preprocess_data> on 2023-07-16 04:24:41.720035+00:00
[2023-07-16T04:24:51.189+0000] {standard_task_runner.py:57} INFO - Started process 988 to run task
[2023-07-16T04:24:51.193+0000] {standard_task_runner.py:84} INFO - Running: ['***', 'tasks', 'run', 'main_dag', 'preprocess_data', 'manual__2023-07-16T04:24:41.720035+00:00', '--job-id', '481', '--raw', '--subdir', 'DAGS_FOLDER/main_dag.py', '--cfg-path', '/tmp/tmplefjedxy']
[2023-07-16T04:24:51.196+0000] {standard_task_runner.py:85} INFO - Job 481: Subtask preprocess_data
[2023-07-16T04:24:51.237+0000] {task_command.py:410} INFO - Running <TaskInstance: main_dag.preprocess_data manual__2023-07-16T04:24:41.720035+00:00 [running]> on host 85db40224008
[2023-07-16T04:24:51.332+0000] {taskinstance.py:1547} INFO - Exporting env vars: AIRFLOW_CTX_DAG_OWNER='***' AIRFLOW_CTX_DAG_ID='main_dag' AIRFLOW_CTX_TASK_ID='preprocess_data' AIRFLOW_CTX_EXECUTION_DATE='2023-07-16T04:24:41.720035+00:00' AIRFLOW_CTX_TRY_NUMBER='1' AIRFLOW_CTX_DAG_RUN_ID='manual__2023-07-16T04:24:41.720035+00:00'
[2023-07-16T04:24:51.382+0000] {taskinstance.py:1824} ERROR - Task failed with exception
Traceback (most recent call last):
  File "/home/airflow/.local/lib/python3.7/site-packages/airflow/operators/python.py", line 181, in execute
    return_value = self.execute_callable()
  File "/home/airflow/.local/lib/python3.7/site-packages/airflow/operators/python.py", line 198, in execute_callable
    return self.python_callable(*self.op_args, **self.op_kwargs)
  File "/opt/airflow/dags/main_dag.py", line 36, in preprocess_data
    graph = nx.read_edgelist(f"data/{kwargs['file_name']}.txt", create_using=nx.Graph(), nodetype=int)
KeyError: 'file_name'
[2023-07-16T04:24:51.392+0000] {taskinstance.py:1350} INFO - Marking task as FAILED. dag_id=main_dag, task_id=preprocess_data, execution_date=20230716T042441, start_date=20230716T042451, end_date=20230716T042451
[2023-07-16T04:24:51.403+0000] {standard_task_runner.py:109} ERROR - Failed to execute job 481 for task preprocess_data ('file_name'; 988)
[2023-07-16T04:24:51.444+0000] {local_task_job_runner.py:225} INFO - Task exited with return code 1
[2023-07-16T04:24:51.477+0000] {taskinstance.py:2653} INFO - 0 downstream tasks scheduled from follow-on schedule check
