[2023-07-17T09:32:08.564+0000] {taskinstance.py:1103} INFO - Dependencies all met for dep_context=non-requeueable deps ti=<TaskInstance: main_dag.data_acquisition manual__2023-07-17T09:32:00.011715+00:00 [queued]>
[2023-07-17T09:32:08.574+0000] {taskinstance.py:1103} INFO - Dependencies all met for dep_context=requeueable deps ti=<TaskInstance: main_dag.data_acquisition manual__2023-07-17T09:32:00.011715+00:00 [queued]>
[2023-07-17T09:32:08.574+0000] {taskinstance.py:1308} INFO - Starting attempt 1 of 1
[2023-07-17T09:32:08.588+0000] {taskinstance.py:1327} INFO - Executing <Task(PythonOperator): data_acquisition> on 2023-07-17 09:32:00.011715+00:00
[2023-07-17T09:32:08.593+0000] {standard_task_runner.py:57} INFO - Started process 700 to run task
[2023-07-17T09:32:08.596+0000] {standard_task_runner.py:84} INFO - Running: ['***', 'tasks', 'run', 'main_dag', 'data_acquisition', 'manual__2023-07-17T09:32:00.011715+00:00', '--job-id', '649', '--raw', '--subdir', 'DAGS_FOLDER/main_dag.py', '--cfg-path', '/tmp/tmpg8ppttnz']
[2023-07-17T09:32:08.600+0000] {standard_task_runner.py:85} INFO - Job 649: Subtask data_acquisition
[2023-07-17T09:32:08.645+0000] {task_command.py:410} INFO - Running <TaskInstance: main_dag.data_acquisition manual__2023-07-17T09:32:00.011715+00:00 [running]> on host a888360a1584
[2023-07-17T09:32:08.734+0000] {taskinstance.py:1547} INFO - Exporting env vars: AIRFLOW_CTX_DAG_OWNER='***' AIRFLOW_CTX_DAG_ID='main_dag' AIRFLOW_CTX_TASK_ID='data_acquisition' AIRFLOW_CTX_EXECUTION_DATE='2023-07-17T09:32:00.011715+00:00' AIRFLOW_CTX_TRY_NUMBER='1' AIRFLOW_CTX_DAG_RUN_ID='manual__2023-07-17T09:32:00.011715+00:00'
[2023-07-17T09:33:54.764+0000] {logging_mixin.py:150} WARNING - /home/***/.local/lib/python3.7/site-packages/wikipedia/wikipedia.py:389 GuessedAtParserWarning: No parser was explicitly specified, so I'm using the best available HTML parser for this system ("lxml"). This usually isn't a problem, but if you run this code on another system, or in a different virtual environment, it may use a different parser and behave differently.

The code that caused this warning is on line 389 of the file /home/***/.local/lib/python3.7/site-packages/wikipedia/wikipedia.py. To get rid of this warning, pass the additional argument 'features="lxml"' to the BeautifulSoup constructor.
[2023-07-17T09:33:54.778+0000] {logging_mixin.py:150} INFO - Could not load Casp
[2023-07-17T09:34:48.909+0000] {logging_mixin.py:150} INFO - Could not load Computer Vision
[2023-07-17T09:35:08.985+0000] {logging_mixin.py:150} INFO - Could not load Dbscan
[2023-07-17T09:35:12.451+0000] {logging_mixin.py:150} INFO - Could not load Data Mining
[2023-07-17T09:36:15.029+0000] {logging_mixin.py:150} INFO - Could not load Github
[2023-07-17T09:36:34.587+0000] {logging_mixin.py:150} INFO - Could not load Google
[2023-07-17T09:37:35.817+0000] {logging_mixin.py:150} INFO - Could not load Identity Matrix
[2023-07-17T09:39:34.854+0000] {logging_mixin.py:150} INFO - Could not load Machine Learning
[2023-07-17T09:40:27.985+0000] {logging_mixin.py:150} INFO - Could not load Multilayer Perceptron
[2023-07-17T09:40:36.082+0000] {logging_mixin.py:150} INFO - Could not load Np-Hard
[2023-07-17T09:43:52.023+0000] {taskinstance.py:1824} ERROR - Task failed with exception
Traceback (most recent call last):
  File "/home/airflow/.local/lib/python3.7/site-packages/urllib3/connectionpool.py", line 721, in urlopen
    chunked=chunked,
  File "/home/airflow/.local/lib/python3.7/site-packages/urllib3/connectionpool.py", line 466, in _make_request
    six.raise_from(e, None)
  File "<string>", line 3, in raise_from
  File "/home/airflow/.local/lib/python3.7/site-packages/urllib3/connectionpool.py", line 461, in _make_request
    httplib_response = conn.getresponse()
  File "/usr/local/lib/python3.7/http/client.py", line 1373, in getresponse
    response.begin()
  File "/usr/local/lib/python3.7/http/client.py", line 319, in begin
    version, status, reason = self._read_status()
  File "/usr/local/lib/python3.7/http/client.py", line 288, in _read_status
    raise RemoteDisconnected("Remote end closed connection without"
http.client.RemoteDisconnected: Remote end closed connection without response

During handling of the above exception, another exception occurred:

Traceback (most recent call last):
  File "/home/airflow/.local/lib/python3.7/site-packages/requests/adapters.py", line 497, in send
    chunked=chunked,
  File "/home/airflow/.local/lib/python3.7/site-packages/urllib3/connectionpool.py", line 799, in urlopen
    method, url, error=e, _pool=self, _stacktrace=sys.exc_info()[2]
  File "/home/airflow/.local/lib/python3.7/site-packages/urllib3/util/retry.py", line 550, in increment
    raise six.reraise(type(error), error, _stacktrace)
  File "/home/airflow/.local/lib/python3.7/site-packages/urllib3/packages/six.py", line 769, in reraise
    raise value.with_traceback(tb)
  File "/home/airflow/.local/lib/python3.7/site-packages/urllib3/connectionpool.py", line 721, in urlopen
    chunked=chunked,
  File "/home/airflow/.local/lib/python3.7/site-packages/urllib3/connectionpool.py", line 466, in _make_request
    six.raise_from(e, None)
  File "<string>", line 3, in raise_from
  File "/home/airflow/.local/lib/python3.7/site-packages/urllib3/connectionpool.py", line 461, in _make_request
    httplib_response = conn.getresponse()
  File "/usr/local/lib/python3.7/http/client.py", line 1373, in getresponse
    response.begin()
  File "/usr/local/lib/python3.7/http/client.py", line 319, in begin
    version, status, reason = self._read_status()
  File "/usr/local/lib/python3.7/http/client.py", line 288, in _read_status
    raise RemoteDisconnected("Remote end closed connection without"
urllib3.exceptions.ProtocolError: ('Connection aborted.', RemoteDisconnected('Remote end closed connection without response'))

During handling of the above exception, another exception occurred:

Traceback (most recent call last):
  File "/home/airflow/.local/lib/python3.7/site-packages/airflow/operators/python.py", line 181, in execute
    return_value = self.execute_callable()
  File "/home/airflow/.local/lib/python3.7/site-packages/airflow/operators/python.py", line 198, in execute_callable
    return self.python_callable(*self.op_args, **self.op_kwargs)
  File "/opt/airflow/dags/main_dag.py", line 81, in data_acquisition
    for link in wiki.links:
  File "/home/airflow/.local/lib/python3.7/site-packages/wikipedia/wikipedia.py", line 612, in links
    'pllimit': 'max'
  File "/home/airflow/.local/lib/python3.7/site-packages/wikipedia/wikipedia.py", line 608, in <listcomp>
    link['title']
  File "/home/airflow/.local/lib/python3.7/site-packages/wikipedia/wikipedia.py", line 413, in __continued_query
    request = _wiki_request(params)
  File "/home/airflow/.local/lib/python3.7/site-packages/wikipedia/wikipedia.py", line 737, in _wiki_request
    r = requests.get(API_URL, params=params, headers=headers)
  File "/home/airflow/.local/lib/python3.7/site-packages/requests/api.py", line 73, in get
    return request("get", url, params=params, **kwargs)
  File "/home/airflow/.local/lib/python3.7/site-packages/requests/api.py", line 59, in request
    return session.request(method=method, url=url, **kwargs)
  File "/home/airflow/.local/lib/python3.7/site-packages/requests/sessions.py", line 589, in request
    resp = self.send(prep, **send_kwargs)
  File "/home/airflow/.local/lib/python3.7/site-packages/requests/sessions.py", line 725, in send
    history = [resp for resp in gen]
  File "/home/airflow/.local/lib/python3.7/site-packages/requests/sessions.py", line 725, in <listcomp>
    history = [resp for resp in gen]
  File "/home/airflow/.local/lib/python3.7/site-packages/requests/sessions.py", line 274, in resolve_redirects
    **adapter_kwargs,
  File "/home/airflow/.local/lib/python3.7/site-packages/requests/sessions.py", line 703, in send
    r = adapter.send(request, **kwargs)
  File "/home/airflow/.local/lib/python3.7/site-packages/requests/adapters.py", line 501, in send
    raise ConnectionError(err, request=request)
requests.exceptions.ConnectionError: ('Connection aborted.', RemoteDisconnected('Remote end closed connection without response'))
[2023-07-17T09:43:52.035+0000] {taskinstance.py:1350} INFO - Marking task as FAILED. dag_id=main_dag, task_id=data_acquisition, execution_date=20230717T093200, start_date=20230717T093208, end_date=20230717T094352
[2023-07-17T09:43:52.050+0000] {standard_task_runner.py:109} ERROR - Failed to execute job 649 for task data_acquisition (('Connection aborted.', RemoteDisconnected('Remote end closed connection without response')); 700)
[2023-07-17T09:43:52.085+0000] {local_task_job_runner.py:225} INFO - Task exited with return code 1
[2023-07-17T09:43:52.141+0000] {taskinstance.py:2653} INFO - 0 downstream tasks scheduled from follow-on schedule check
