[2023-07-16T13:28:11.964+0000] {taskinstance.py:1103} INFO - Dependencies all met for dep_context=non-requeueable deps ti=<TaskInstance: main_dag.export_figures manual__2023-07-16T13:28:00.348347+00:00 [queued]>
[2023-07-16T13:28:11.974+0000] {taskinstance.py:1103} INFO - Dependencies all met for dep_context=requeueable deps ti=<TaskInstance: main_dag.export_figures manual__2023-07-16T13:28:00.348347+00:00 [queued]>
[2023-07-16T13:28:11.975+0000] {taskinstance.py:1308} INFO - Starting attempt 1 of 1
[2023-07-16T13:28:11.989+0000] {taskinstance.py:1327} INFO - Executing <Task(BashOperator): export_figures> on 2023-07-16 13:28:00.348347+00:00
[2023-07-16T13:28:11.994+0000] {standard_task_runner.py:57} INFO - Started process 673 to run task
[2023-07-16T13:28:11.996+0000] {standard_task_runner.py:84} INFO - Running: ['***', 'tasks', 'run', 'main_dag', 'export_figures', 'manual__2023-07-16T13:28:00.348347+00:00', '--job-id', '508', '--raw', '--subdir', 'DAGS_FOLDER/main_dag.py', '--cfg-path', '/tmp/tmpknu9gsoq']
[2023-07-16T13:28:12.000+0000] {standard_task_runner.py:85} INFO - Job 508: Subtask export_figures
[2023-07-16T13:28:12.040+0000] {task_command.py:410} INFO - Running <TaskInstance: main_dag.export_figures manual__2023-07-16T13:28:00.348347+00:00 [running]> on host e866793b1059
[2023-07-16T13:28:12.129+0000] {taskinstance.py:1547} INFO - Exporting env vars: AIRFLOW_CTX_DAG_OWNER='***' AIRFLOW_CTX_DAG_ID='main_dag' AIRFLOW_CTX_TASK_ID='export_figures' AIRFLOW_CTX_EXECUTION_DATE='2023-07-16T13:28:00.348347+00:00' AIRFLOW_CTX_TRY_NUMBER='1' AIRFLOW_CTX_DAG_RUN_ID='manual__2023-07-16T13:28:00.348347+00:00'
[2023-07-16T13:28:12.131+0000] {subprocess.py:63} INFO - Tmp dir root location: /tmp
[2023-07-16T13:28:12.131+0000] {subprocess.py:75} INFO - Running command: ['/bin/bash', '-c', 'docker cp e866793b1059:./figures ./figures']
[2023-07-16T13:28:12.142+0000] {subprocess.py:86} INFO - Output:
[2023-07-16T13:28:12.161+0000] {subprocess.py:93} INFO - Cannot connect to the Docker daemon at unix:///var/run/docker.sock. Is the docker daemon running?
[2023-07-16T13:28:12.163+0000] {subprocess.py:97} INFO - Command exited with return code 1
[2023-07-16T13:28:12.174+0000] {taskinstance.py:1824} ERROR - Task failed with exception
Traceback (most recent call last):
  File "/home/airflow/.local/lib/python3.7/site-packages/airflow/operators/bash.py", line 211, in execute
    f"Bash command failed. The command returned a non-zero exit code {result.exit_code}."
airflow.exceptions.AirflowException: Bash command failed. The command returned a non-zero exit code 1.
[2023-07-16T13:28:12.178+0000] {taskinstance.py:1350} INFO - Marking task as FAILED. dag_id=main_dag, task_id=export_figures, execution_date=20230716T132800, start_date=20230716T132811, end_date=20230716T132812
[2023-07-16T13:28:12.190+0000] {standard_task_runner.py:109} ERROR - Failed to execute job 508 for task export_figures (Bash command failed. The command returned a non-zero exit code 1.; 673)
[2023-07-16T13:28:12.208+0000] {local_task_job_runner.py:225} INFO - Task exited with return code 1
[2023-07-16T13:28:12.226+0000] {taskinstance.py:2653} INFO - 0 downstream tasks scheduled from follow-on schedule check
