[2023-07-16T16:13:45.429+0000] {taskinstance.py:1103} INFO - Dependencies all met for dep_context=non-requeueable deps ti=<TaskInstance: main_dag.make_figures.plot_count_cdf manual__2023-07-16T16:13:34.261311+00:00 [queued]>
[2023-07-16T16:13:45.441+0000] {taskinstance.py:1103} INFO - Dependencies all met for dep_context=requeueable deps ti=<TaskInstance: main_dag.make_figures.plot_count_cdf manual__2023-07-16T16:13:34.261311+00:00 [queued]>
[2023-07-16T16:13:45.442+0000] {taskinstance.py:1308} INFO - Starting attempt 1 of 1
[2023-07-16T16:13:45.457+0000] {taskinstance.py:1327} INFO - Executing <Task(PythonOperator): make_figures.plot_count_cdf> on 2023-07-16 16:13:34.261311+00:00
[2023-07-16T16:13:45.464+0000] {standard_task_runner.py:57} INFO - Started process 2575 to run task
[2023-07-16T16:13:45.467+0000] {standard_task_runner.py:84} INFO - Running: ['***', 'tasks', 'run', 'main_dag', 'make_figures.plot_count_cdf', 'manual__2023-07-16T16:13:34.261311+00:00', '--job-id', '599', '--raw', '--subdir', 'DAGS_FOLDER/main_dag.py', '--cfg-path', '/tmp/tmpt2qvge8e']
[2023-07-16T16:13:45.472+0000] {standard_task_runner.py:85} INFO - Job 599: Subtask make_figures.plot_count_cdf
[2023-07-16T16:13:45.541+0000] {task_command.py:410} INFO - Running <TaskInstance: main_dag.make_figures.plot_count_cdf manual__2023-07-16T16:13:34.261311+00:00 [running]> on host 1696d5f40b5e
[2023-07-16T16:13:45.807+0000] {taskinstance.py:1547} INFO - Exporting env vars: AIRFLOW_CTX_DAG_OWNER='***' AIRFLOW_CTX_DAG_ID='main_dag' AIRFLOW_CTX_TASK_ID='make_figures.plot_count_cdf' AIRFLOW_CTX_EXECUTION_DATE='2023-07-16T16:13:34.261311+00:00' AIRFLOW_CTX_TRY_NUMBER='1' AIRFLOW_CTX_DAG_RUN_ID='manual__2023-07-16T16:13:34.261311+00:00'
[2023-07-16T16:13:46.926+0000] {taskinstance.py:1824} ERROR - Task failed with exception
Traceback (most recent call last):
  File "/home/airflow/.local/lib/python3.7/site-packages/airflow/operators/python.py", line 181, in execute
    return_value = self.execute_callable()
  File "/home/airflow/.local/lib/python3.7/site-packages/airflow/operators/python.py", line 198, in execute_callable
    return self.python_callable(*self.op_args, **self.op_kwargs)
  File "/opt/airflow/dags/main_dag.py", line 167, in count_cdf_figure
    sns.histplot(degree_sequence, bins=7, label="Count", ax=ax)
NameError: name 'sns' is not defined
[2023-07-16T16:13:46.936+0000] {taskinstance.py:1350} INFO - Marking task as FAILED. dag_id=main_dag, task_id=make_figures.plot_count_cdf, execution_date=20230716T161334, start_date=20230716T161345, end_date=20230716T161346
[2023-07-16T16:13:46.950+0000] {standard_task_runner.py:109} ERROR - Failed to execute job 599 for task make_figures.plot_count_cdf (name 'sns' is not defined; 2575)
[2023-07-16T16:13:47.004+0000] {local_task_job_runner.py:225} INFO - Task exited with return code 1
[2023-07-16T16:13:47.043+0000] {taskinstance.py:2653} INFO - 0 downstream tasks scheduled from follow-on schedule check
