[2023-07-17T08:38:27.087+0000] {taskinstance.py:1103} INFO - Dependencies all met for dep_context=non-requeueable deps ti=<TaskInstance: main_dag.preprocessing.data_acquisition manual__2023-07-17T08:37:53.810518+00:00 [queued]>
[2023-07-17T08:38:27.096+0000] {taskinstance.py:1103} INFO - Dependencies all met for dep_context=requeueable deps ti=<TaskInstance: main_dag.preprocessing.data_acquisition manual__2023-07-17T08:37:53.810518+00:00 [queued]>
[2023-07-17T08:38:27.096+0000] {taskinstance.py:1308} INFO - Starting attempt 1 of 1
[2023-07-17T08:38:27.112+0000] {taskinstance.py:1327} INFO - Executing <Task(PythonOperator): preprocessing.data_acquisition> on 2023-07-17 08:37:53.810518+00:00
[2023-07-17T08:38:27.118+0000] {standard_task_runner.py:57} INFO - Started process 4060 to run task
[2023-07-17T08:38:27.120+0000] {standard_task_runner.py:84} INFO - Running: ['***', 'tasks', 'run', 'main_dag', 'preprocessing.data_acquisition', 'manual__2023-07-17T08:37:53.810518+00:00', '--job-id', '626', '--raw', '--subdir', 'DAGS_FOLDER/main_dag.py', '--cfg-path', '/tmp/tmp09ctd6re']
[2023-07-17T08:38:27.124+0000] {standard_task_runner.py:85} INFO - Job 626: Subtask preprocessing.data_acquisition
[2023-07-17T08:38:27.170+0000] {task_command.py:410} INFO - Running <TaskInstance: main_dag.preprocessing.data_acquisition manual__2023-07-17T08:37:53.810518+00:00 [running]> on host 0314a966ffa9
[2023-07-17T08:38:27.265+0000] {taskinstance.py:1547} INFO - Exporting env vars: AIRFLOW_CTX_DAG_OWNER='***' AIRFLOW_CTX_DAG_ID='main_dag' AIRFLOW_CTX_TASK_ID='preprocessing.data_acquisition' AIRFLOW_CTX_EXECUTION_DATE='2023-07-17T08:37:53.810518+00:00' AIRFLOW_CTX_TRY_NUMBER='1' AIRFLOW_CTX_DAG_RUN_ID='manual__2023-07-17T08:37:53.810518+00:00'
[2023-07-17T08:38:32.261+0000] {taskinstance.py:1824} ERROR - Task failed with exception
Traceback (most recent call last):
  File "/home/airflow/.local/lib/python3.7/site-packages/airflow/operators/python.py", line 181, in execute
    return_value = self.execute_callable()
  File "/home/airflow/.local/lib/python3.7/site-packages/airflow/operators/python.py", line 198, in execute_callable
    return self.python_callable(*self.op_args, **self.op_kwargs)
  File "/opt/airflow/dags/main_dag.py", line 64, in data_acquisition
    if link not in STOPS and not link.startswith("List Of"):
NameError: name 'STOPS' is not defined
[2023-07-17T08:38:32.272+0000] {taskinstance.py:1350} INFO - Marking task as FAILED. dag_id=main_dag, task_id=preprocessing.data_acquisition, execution_date=20230717T083753, start_date=20230717T083827, end_date=20230717T083832
[2023-07-17T08:38:32.294+0000] {standard_task_runner.py:109} ERROR - Failed to execute job 626 for task preprocessing.data_acquisition (name 'STOPS' is not defined; 4060)
[2023-07-17T08:38:32.321+0000] {local_task_job_runner.py:225} INFO - Task exited with return code 1
[2023-07-17T08:38:32.347+0000] {taskinstance.py:2653} INFO - 0 downstream tasks scheduled from follow-on schedule check
