[2023-07-16T01:33:37.320+0000] {taskinstance.py:1103} INFO - Dependencies all met for dep_context=non-requeueable deps ti=<TaskInstance: main_dag.tsk1 manual__2023-07-16T01:33:36.394716+00:00 [queued]>
[2023-07-16T01:33:37.330+0000] {taskinstance.py:1103} INFO - Dependencies all met for dep_context=requeueable deps ti=<TaskInstance: main_dag.tsk1 manual__2023-07-16T01:33:36.394716+00:00 [queued]>
[2023-07-16T01:33:37.330+0000] {taskinstance.py:1308} INFO - Starting attempt 1 of 1
[2023-07-16T01:33:37.344+0000] {taskinstance.py:1327} INFO - Executing <Task(BashOperator): tsk1> on 2023-07-16 01:33:36.394716+00:00
[2023-07-16T01:33:37.349+0000] {standard_task_runner.py:57} INFO - Started process 2338 to run task
[2023-07-16T01:33:37.353+0000] {standard_task_runner.py:84} INFO - Running: ['***', 'tasks', 'run', 'main_dag', 'tsk1', 'manual__2023-07-16T01:33:36.394716+00:00', '--job-id', '418', '--raw', '--subdir', 'DAGS_FOLDER/main_dag.py', '--cfg-path', '/tmp/tmpusf4xvoh']
[2023-07-16T01:33:37.354+0000] {standard_task_runner.py:85} INFO - Job 418: Subtask tsk1
[2023-07-16T01:33:37.396+0000] {task_command.py:410} INFO - Running <TaskInstance: main_dag.tsk1 manual__2023-07-16T01:33:36.394716+00:00 [running]> on host 3be1cdcf9db5
[2023-07-16T01:33:37.493+0000] {taskinstance.py:1547} INFO - Exporting env vars: AIRFLOW_CTX_DAG_OWNER='***' AIRFLOW_CTX_DAG_ID='main_dag' AIRFLOW_CTX_TASK_ID='tsk1' AIRFLOW_CTX_EXECUTION_DATE='2023-07-16T01:33:36.394716+00:00' AIRFLOW_CTX_TRY_NUMBER='1' AIRFLOW_CTX_DAG_RUN_ID='manual__2023-07-16T01:33:36.394716+00:00'
[2023-07-16T01:33:37.495+0000] {subprocess.py:63} INFO - Tmp dir root location: /tmp
[2023-07-16T01:33:37.495+0000] {subprocess.py:75} INFO - Running command: ['/bin/bash', '-c', 'docker exec -it ***-project_***-scheduler_1 bash && pip install networkx']
[2023-07-16T01:33:37.507+0000] {subprocess.py:86} INFO - Output:
[2023-07-16T01:33:37.527+0000] {subprocess.py:93} INFO - Cannot connect to the Docker daemon at unix:///var/run/docker.sock. Is the docker daemon running?
[2023-07-16T01:33:37.530+0000] {subprocess.py:97} INFO - Command exited with return code 1
[2023-07-16T01:33:37.540+0000] {taskinstance.py:1824} ERROR - Task failed with exception
Traceback (most recent call last):
  File "/home/airflow/.local/lib/python3.7/site-packages/airflow/operators/bash.py", line 211, in execute
    f"Bash command failed. The command returned a non-zero exit code {result.exit_code}."
airflow.exceptions.AirflowException: Bash command failed. The command returned a non-zero exit code 1.
[2023-07-16T01:33:37.544+0000] {taskinstance.py:1350} INFO - Marking task as FAILED. dag_id=main_dag, task_id=tsk1, execution_date=20230716T013336, start_date=20230716T013337, end_date=20230716T013337
[2023-07-16T01:33:37.556+0000] {standard_task_runner.py:109} ERROR - Failed to execute job 418 for task tsk1 (Bash command failed. The command returned a non-zero exit code 1.; 2338)
[2023-07-16T01:33:37.604+0000] {local_task_job_runner.py:225} INFO - Task exited with return code 1
[2023-07-16T01:33:37.623+0000] {taskinstance.py:2653} INFO - 0 downstream tasks scheduled from follow-on schedule check
