[2023-07-18T00:01:44.160+0000] {taskinstance.py:1103} INFO - Dependencies all met for dep_context=non-requeueable deps ti=<TaskInstance: main_dag.make_figures.plot_all_together manual__2023-07-17T23:51:06.872926+00:00 [queued]>
[2023-07-18T00:01:44.172+0000] {taskinstance.py:1103} INFO - Dependencies all met for dep_context=requeueable deps ti=<TaskInstance: main_dag.make_figures.plot_all_together manual__2023-07-17T23:51:06.872926+00:00 [queued]>
[2023-07-18T00:01:44.173+0000] {taskinstance.py:1308} INFO - Starting attempt 1 of 1
[2023-07-18T00:01:44.191+0000] {taskinstance.py:1327} INFO - Executing <Task(PythonOperator): make_figures.plot_all_together> on 2023-07-17 23:51:06.872926+00:00
[2023-07-18T00:01:44.198+0000] {standard_task_runner.py:57} INFO - Started process 691 to run task
[2023-07-18T00:01:44.200+0000] {standard_task_runner.py:84} INFO - Running: ['***', 'tasks', 'run', 'main_dag', 'make_figures.plot_all_together', 'manual__2023-07-17T23:51:06.872926+00:00', '--job-id', '893', '--raw', '--subdir', 'DAGS_FOLDER/main_dag.py', '--cfg-path', '/tmp/tmpfy0ea1ri']
[2023-07-18T00:01:44.202+0000] {standard_task_runner.py:85} INFO - Job 893: Subtask make_figures.plot_all_together
[2023-07-18T00:01:44.260+0000] {task_command.py:410} INFO - Running <TaskInstance: main_dag.make_figures.plot_all_together manual__2023-07-17T23:51:06.872926+00:00 [running]> on host 47ead6a42877
[2023-07-18T00:01:44.397+0000] {taskinstance.py:1547} INFO - Exporting env vars: AIRFLOW_CTX_DAG_OWNER='***' AIRFLOW_CTX_DAG_ID='main_dag' AIRFLOW_CTX_TASK_ID='make_figures.plot_all_together' AIRFLOW_CTX_EXECUTION_DATE='2023-07-17T23:51:06.872926+00:00' AIRFLOW_CTX_TRY_NUMBER='1' AIRFLOW_CTX_DAG_RUN_ID='manual__2023-07-17T23:51:06.872926+00:00'
[2023-07-18T00:01:45.455+0000] {font_manager.py:1443} INFO - generated new fontManager
[2023-07-18T00:07:20.551+0000] {job.py:213} ERROR - Job heartbeat got an exception
Traceback (most recent call last):
  File "/home/airflow/.local/lib/python3.7/site-packages/sqlalchemy/engine/base.py", line 3371, in _wrap_pool_connect
    return fn()
  File "/home/airflow/.local/lib/python3.7/site-packages/sqlalchemy/pool/base.py", line 327, in connect
    return _ConnectionFairy._checkout(self)
  File "/home/airflow/.local/lib/python3.7/site-packages/sqlalchemy/pool/base.py", line 894, in _checkout
    fairy = _ConnectionRecord.checkout(pool)
  File "/home/airflow/.local/lib/python3.7/site-packages/sqlalchemy/pool/base.py", line 493, in checkout
    rec = pool._do_get()
  File "/home/airflow/.local/lib/python3.7/site-packages/sqlalchemy/pool/impl.py", line 256, in _do_get
    return self._create_connection()
  File "/home/airflow/.local/lib/python3.7/site-packages/sqlalchemy/pool/base.py", line 273, in _create_connection
    return _ConnectionRecord(self)
  File "/home/airflow/.local/lib/python3.7/site-packages/sqlalchemy/pool/base.py", line 388, in __init__
    self.__connect()
  File "/home/airflow/.local/lib/python3.7/site-packages/sqlalchemy/pool/base.py", line 691, in __connect
    pool.logger.debug("Error on connect(): %s", e)
  File "/home/airflow/.local/lib/python3.7/site-packages/sqlalchemy/util/langhelpers.py", line 72, in __exit__
    with_traceback=exc_tb,
  File "/home/airflow/.local/lib/python3.7/site-packages/sqlalchemy/util/compat.py", line 211, in raise_
    raise exception
  File "/home/airflow/.local/lib/python3.7/site-packages/sqlalchemy/pool/base.py", line 686, in __connect
    self.dbapi_connection = connection = pool._invoke_creator(self)
  File "/home/airflow/.local/lib/python3.7/site-packages/sqlalchemy/engine/create.py", line 574, in connect
    return dialect.connect(*cargs, **cparams)
  File "/home/airflow/.local/lib/python3.7/site-packages/sqlalchemy/engine/default.py", line 598, in connect
    return self.dbapi.connect(*cargs, **cparams)
  File "/home/airflow/.local/lib/python3.7/site-packages/psycopg2/__init__.py", line 122, in connect
    conn = _connect(dsn, connection_factory=connection_factory, **kwasync)
psycopg2.OperationalError: could not translate host name "postgres" to address: Temporary failure in name resolution


The above exception was the direct cause of the following exception:

Traceback (most recent call last):
  File "/home/airflow/.local/lib/python3.7/site-packages/airflow/jobs/job.py", line 184, in heartbeat
    session.merge(self)
  File "/home/airflow/.local/lib/python3.7/site-packages/sqlalchemy/orm/session.py", line 3062, in merge
    _resolve_conflict_map=_resolve_conflict_map,
  File "/home/airflow/.local/lib/python3.7/site-packages/sqlalchemy/orm/session.py", line 3140, in _merge
    options=options,
  File "/home/airflow/.local/lib/python3.7/site-packages/sqlalchemy/orm/session.py", line 2861, in get
    execution_options=execution_options,
  File "/home/airflow/.local/lib/python3.7/site-packages/sqlalchemy/orm/session.py", line 2979, in _get_impl
    load_options=load_options,
  File "/home/airflow/.local/lib/python3.7/site-packages/sqlalchemy/orm/loading.py", line 534, in load_on_pk_identity
    bind_arguments=bind_arguments,
  File "/home/airflow/.local/lib/python3.7/site-packages/sqlalchemy/orm/session.py", line 1716, in execute
    conn = self._connection_for_bind(bind)
  File "/home/airflow/.local/lib/python3.7/site-packages/sqlalchemy/orm/session.py", line 1556, in _connection_for_bind
    engine, execution_options
  File "/home/airflow/.local/lib/python3.7/site-packages/sqlalchemy/orm/session.py", line 750, in _connection_for_bind
    conn = bind.connect()
  File "/home/airflow/.local/lib/python3.7/site-packages/sqlalchemy/engine/base.py", line 3325, in connect
    return self._connection_cls(self, close_with_result=close_with_result)
  File "/home/airflow/.local/lib/python3.7/site-packages/sqlalchemy/engine/base.py", line 96, in __init__
    else engine.raw_connection()
  File "/home/airflow/.local/lib/python3.7/site-packages/sqlalchemy/engine/base.py", line 3404, in raw_connection
    return self._wrap_pool_connect(self.pool.connect, _connection)
  File "/home/airflow/.local/lib/python3.7/site-packages/sqlalchemy/engine/base.py", line 3375, in _wrap_pool_connect
    e, dialect, self
  File "/home/airflow/.local/lib/python3.7/site-packages/sqlalchemy/engine/base.py", line 2209, in _handle_dbapi_exception_noconnection
    sqlalchemy_exception, with_traceback=exc_info[2], from_=e
  File "/home/airflow/.local/lib/python3.7/site-packages/sqlalchemy/util/compat.py", line 211, in raise_
    raise exception
  File "/home/airflow/.local/lib/python3.7/site-packages/sqlalchemy/engine/base.py", line 3371, in _wrap_pool_connect
    return fn()
  File "/home/airflow/.local/lib/python3.7/site-packages/sqlalchemy/pool/base.py", line 327, in connect
    return _ConnectionFairy._checkout(self)
  File "/home/airflow/.local/lib/python3.7/site-packages/sqlalchemy/pool/base.py", line 894, in _checkout
    fairy = _ConnectionRecord.checkout(pool)
  File "/home/airflow/.local/lib/python3.7/site-packages/sqlalchemy/pool/base.py", line 493, in checkout
    rec = pool._do_get()
  File "/home/airflow/.local/lib/python3.7/site-packages/sqlalchemy/pool/impl.py", line 256, in _do_get
    return self._create_connection()
  File "/home/airflow/.local/lib/python3.7/site-packages/sqlalchemy/pool/base.py", line 273, in _create_connection
    return _ConnectionRecord(self)
  File "/home/airflow/.local/lib/python3.7/site-packages/sqlalchemy/pool/base.py", line 388, in __init__
    self.__connect()
  File "/home/airflow/.local/lib/python3.7/site-packages/sqlalchemy/pool/base.py", line 691, in __connect
    pool.logger.debug("Error on connect(): %s", e)
  File "/home/airflow/.local/lib/python3.7/site-packages/sqlalchemy/util/langhelpers.py", line 72, in __exit__
    with_traceback=exc_tb,
  File "/home/airflow/.local/lib/python3.7/site-packages/sqlalchemy/util/compat.py", line 211, in raise_
    raise exception
  File "/home/airflow/.local/lib/python3.7/site-packages/sqlalchemy/pool/base.py", line 686, in __connect
    self.dbapi_connection = connection = pool._invoke_creator(self)
  File "/home/airflow/.local/lib/python3.7/site-packages/sqlalchemy/engine/create.py", line 574, in connect
    return dialect.connect(*cargs, **cparams)
  File "/home/airflow/.local/lib/python3.7/site-packages/sqlalchemy/engine/default.py", line 598, in connect
    return self.dbapi.connect(*cargs, **cparams)
  File "/home/airflow/.local/lib/python3.7/site-packages/psycopg2/__init__.py", line 122, in connect
    conn = _connect(dsn, connection_factory=connection_factory, **kwasync)
sqlalchemy.exc.OperationalError: (psycopg2.OperationalError) could not translate host name "postgres" to address: Temporary failure in name resolution

(Background on this error at: https://sqlalche.me/e/14/e3q8)
[2023-07-18T00:09:33.566+0000] {local_task_job_runner.py:115} ERROR - Received SIGTERM. Terminating subprocesses
[2023-07-18T00:09:33.867+0000] {process_utils.py:135} INFO - Sending Signals.SIGTERM to group 691. PIDs of all processes in the group: [691]
[2023-07-18T00:09:33.913+0000] {process_utils.py:86} INFO - Sending the signal Signals.SIGTERM to group 691
[2023-07-18T00:09:34.016+0000] {taskinstance.py:1517} ERROR - Received SIGTERM. Terminating subprocesses.
[2023-07-18T00:09:34.832+0000] {taskinstance.py:1824} ERROR - Task failed with exception
Traceback (most recent call last):
  File "/home/airflow/.local/lib/python3.7/site-packages/airflow/operators/python.py", line 181, in execute
    return_value = self.execute_callable()
  File "/home/airflow/.local/lib/python3.7/site-packages/airflow/operators/python.py", line 198, in execute_callable
    return self.python_callable(*self.op_args, **self.op_kwargs)
  File "/opt/airflow/dags/main_dag.py", line 185, in all_together_figure
    nx.draw_networkx_edges(graph, pos=pos, alpha=0.4, ax=ax[1,0])
  File "/home/airflow/.local/lib/python3.7/site-packages/networkx/drawing/nx_pylab.py", line 862, in draw_networkx_edges
    edge_viz_obj = _draw_networkx_edges_fancy_arrow_patch()
  File "/home/airflow/.local/lib/python3.7/site-packages/networkx/drawing/nx_pylab.py", line 840, in _draw_networkx_edges_fancy_arrow_patch
    ax.add_patch(arrow)
  File "/home/airflow/.local/lib/python3.7/site-packages/matplotlib/axes/_base.py", line 2363, in add_patch
    self._update_patch_limits(p)
  File "/home/airflow/.local/lib/python3.7/site-packages/matplotlib/axes/_base.py", line 2381, in _update_patch_limits
    p = patch.get_path()
  File "/home/airflow/.local/lib/python3.7/site-packages/matplotlib/patches.py", line 4448, in get_path
    _path = Path.make_compound_path(*_path)
  File "/home/airflow/.local/lib/python3.7/site-packages/matplotlib/path.py", line 335, in make_compound_path
    vertices = vertices[not_stop_mask, :]
  File "/home/airflow/.local/lib/python3.7/site-packages/airflow/models/taskinstance.py", line 1519, in signal_handler
    raise AirflowException("Task received SIGTERM signal")
airflow.exceptions.AirflowException: Task received SIGTERM signal
[2023-07-18T00:09:34.863+0000] {taskinstance.py:1350} INFO - Marking task as FAILED. dag_id=main_dag, task_id=make_figures.plot_all_together, execution_date=20230717T235106, start_date=20230718T000144, end_date=20230718T000934
[2023-07-18T00:09:34.911+0000] {standard_task_runner.py:109} ERROR - Failed to execute job 893 for task make_figures.plot_all_together (Task received SIGTERM signal; 691)
[2023-07-18T00:09:35.086+0000] {process_utils.py:79} INFO - Process psutil.Process(pid=691, status='terminated', exitcode=1, started='00:01:43') (691) terminated with exit code 1
[2023-07-18T00:09:35.092+0000] {local_task_job_runner.py:225} INFO - Task exited with return code 143
[2023-07-18T00:09:35.292+0000] {taskinstance.py:2653} INFO - 0 downstream tasks scheduled from follow-on schedule check
