[2023-07-18T00:01:44.177+0000] {taskinstance.py:1103} INFO - Dependencies all met for dep_context=non-requeueable deps ti=<TaskInstance: main_dag.make_figures.plot_k_core_shell manual__2023-07-17T23:51:06.872926+00:00 [queued]>
[2023-07-18T00:01:44.189+0000] {taskinstance.py:1103} INFO - Dependencies all met for dep_context=requeueable deps ti=<TaskInstance: main_dag.make_figures.plot_k_core_shell manual__2023-07-17T23:51:06.872926+00:00 [queued]>
[2023-07-18T00:01:44.190+0000] {taskinstance.py:1308} INFO - Starting attempt 1 of 1
[2023-07-18T00:01:44.211+0000] {taskinstance.py:1327} INFO - Executing <Task(PythonOperator): make_figures.plot_k_core_shell> on 2023-07-17 23:51:06.872926+00:00
[2023-07-18T00:01:44.216+0000] {standard_task_runner.py:57} INFO - Started process 692 to run task
[2023-07-18T00:01:44.220+0000] {standard_task_runner.py:84} INFO - Running: ['***', 'tasks', 'run', 'main_dag', 'make_figures.plot_k_core_shell', 'manual__2023-07-17T23:51:06.872926+00:00', '--job-id', '894', '--raw', '--subdir', 'DAGS_FOLDER/main_dag.py', '--cfg-path', '/tmp/tmph8r287f0']
[2023-07-18T00:01:44.221+0000] {standard_task_runner.py:85} INFO - Job 894: Subtask make_figures.plot_k_core_shell
[2023-07-18T00:01:44.289+0000] {task_command.py:410} INFO - Running <TaskInstance: main_dag.make_figures.plot_k_core_shell manual__2023-07-17T23:51:06.872926+00:00 [running]> on host 47ead6a42877
[2023-07-18T00:01:44.419+0000] {taskinstance.py:1547} INFO - Exporting env vars: AIRFLOW_CTX_DAG_OWNER='***' AIRFLOW_CTX_DAG_ID='main_dag' AIRFLOW_CTX_TASK_ID='make_figures.plot_k_core_shell' AIRFLOW_CTX_EXECUTION_DATE='2023-07-17T23:51:06.872926+00:00' AIRFLOW_CTX_TRY_NUMBER='1' AIRFLOW_CTX_DAG_RUN_ID='manual__2023-07-17T23:51:06.872926+00:00'
[2023-07-18T00:01:45.762+0000] {font_manager.py:1443} INFO - generated new fontManager
[2023-07-18T00:07:10.511+0000] {job.py:213} ERROR - Job heartbeat got an exception
Traceback (most recent call last):
  File "/home/airflow/.local/lib/python3.7/site-packages/sqlalchemy/engine/base.py", line 3371, in _wrap_pool_connect
    return fn()
  File "/home/airflow/.local/lib/python3.7/site-packages/sqlalchemy/pool/base.py", line 327, in connect
    return _ConnectionFairy._checkout(self)
  File "/home/airflow/.local/lib/python3.7/site-packages/sqlalchemy/pool/base.py", line 894, in _checkout
    fairy = _ConnectionRecord.checkout(pool)
  File "/home/airflow/.local/lib/python3.7/site-packages/sqlalchemy/pool/base.py", line 493, in checkout
    rec = pool._do_get()
  File "/home/airflow/.local/lib/python3.7/site-packages/sqlalchemy/pool/impl.py", line 256, in _do_get
    return self._create_connection()
  File "/home/airflow/.local/lib/python3.7/site-packages/sqlalchemy/pool/base.py", line 273, in _create_connection
    return _ConnectionRecord(self)
  File "/home/airflow/.local/lib/python3.7/site-packages/sqlalchemy/pool/base.py", line 388, in __init__
    self.__connect()
  File "/home/airflow/.local/lib/python3.7/site-packages/sqlalchemy/pool/base.py", line 691, in __connect
    pool.logger.debug("Error on connect(): %s", e)
  File "/home/airflow/.local/lib/python3.7/site-packages/sqlalchemy/util/langhelpers.py", line 72, in __exit__
    with_traceback=exc_tb,
  File "/home/airflow/.local/lib/python3.7/site-packages/sqlalchemy/util/compat.py", line 211, in raise_
    raise exception
  File "/home/airflow/.local/lib/python3.7/site-packages/sqlalchemy/pool/base.py", line 686, in __connect
    self.dbapi_connection = connection = pool._invoke_creator(self)
  File "/home/airflow/.local/lib/python3.7/site-packages/sqlalchemy/engine/create.py", line 574, in connect
    return dialect.connect(*cargs, **cparams)
  File "/home/airflow/.local/lib/python3.7/site-packages/sqlalchemy/engine/default.py", line 598, in connect
    return self.dbapi.connect(*cargs, **cparams)
  File "/home/airflow/.local/lib/python3.7/site-packages/psycopg2/__init__.py", line 122, in connect
    conn = _connect(dsn, connection_factory=connection_factory, **kwasync)
psycopg2.OperationalError: could not translate host name "postgres" to address: Temporary failure in name resolution


The above exception was the direct cause of the following exception:

Traceback (most recent call last):
  File "/home/airflow/.local/lib/python3.7/site-packages/airflow/jobs/job.py", line 184, in heartbeat
    session.merge(self)
  File "/home/airflow/.local/lib/python3.7/site-packages/sqlalchemy/orm/session.py", line 3062, in merge
    _resolve_conflict_map=_resolve_conflict_map,
  File "/home/airflow/.local/lib/python3.7/site-packages/sqlalchemy/orm/session.py", line 3140, in _merge
    options=options,
  File "/home/airflow/.local/lib/python3.7/site-packages/sqlalchemy/orm/session.py", line 2861, in get
    execution_options=execution_options,
  File "/home/airflow/.local/lib/python3.7/site-packages/sqlalchemy/orm/session.py", line 2979, in _get_impl
    load_options=load_options,
  File "/home/airflow/.local/lib/python3.7/site-packages/sqlalchemy/orm/loading.py", line 534, in load_on_pk_identity
    bind_arguments=bind_arguments,
  File "/home/airflow/.local/lib/python3.7/site-packages/sqlalchemy/orm/session.py", line 1716, in execute
    conn = self._connection_for_bind(bind)
  File "/home/airflow/.local/lib/python3.7/site-packages/sqlalchemy/orm/session.py", line 1556, in _connection_for_bind
    engine, execution_options
  File "/home/airflow/.local/lib/python3.7/site-packages/sqlalchemy/orm/session.py", line 750, in _connection_for_bind
    conn = bind.connect()
  File "/home/airflow/.local/lib/python3.7/site-packages/sqlalchemy/engine/base.py", line 3325, in connect
    return self._connection_cls(self, close_with_result=close_with_result)
  File "/home/airflow/.local/lib/python3.7/site-packages/sqlalchemy/engine/base.py", line 96, in __init__
    else engine.raw_connection()
  File "/home/airflow/.local/lib/python3.7/site-packages/sqlalchemy/engine/base.py", line 3404, in raw_connection
    return self._wrap_pool_connect(self.pool.connect, _connection)
  File "/home/airflow/.local/lib/python3.7/site-packages/sqlalchemy/engine/base.py", line 3375, in _wrap_pool_connect
    e, dialect, self
  File "/home/airflow/.local/lib/python3.7/site-packages/sqlalchemy/engine/base.py", line 2209, in _handle_dbapi_exception_noconnection
    sqlalchemy_exception, with_traceback=exc_info[2], from_=e
  File "/home/airflow/.local/lib/python3.7/site-packages/sqlalchemy/util/compat.py", line 211, in raise_
    raise exception
  File "/home/airflow/.local/lib/python3.7/site-packages/sqlalchemy/engine/base.py", line 3371, in _wrap_pool_connect
    return fn()
  File "/home/airflow/.local/lib/python3.7/site-packages/sqlalchemy/pool/base.py", line 327, in connect
    return _ConnectionFairy._checkout(self)
  File "/home/airflow/.local/lib/python3.7/site-packages/sqlalchemy/pool/base.py", line 894, in _checkout
    fairy = _ConnectionRecord.checkout(pool)
  File "/home/airflow/.local/lib/python3.7/site-packages/sqlalchemy/pool/base.py", line 493, in checkout
    rec = pool._do_get()
  File "/home/airflow/.local/lib/python3.7/site-packages/sqlalchemy/pool/impl.py", line 256, in _do_get
    return self._create_connection()
  File "/home/airflow/.local/lib/python3.7/site-packages/sqlalchemy/pool/base.py", line 273, in _create_connection
    return _ConnectionRecord(self)
  File "/home/airflow/.local/lib/python3.7/site-packages/sqlalchemy/pool/base.py", line 388, in __init__
    self.__connect()
  File "/home/airflow/.local/lib/python3.7/site-packages/sqlalchemy/pool/base.py", line 691, in __connect
    pool.logger.debug("Error on connect(): %s", e)
  File "/home/airflow/.local/lib/python3.7/site-packages/sqlalchemy/util/langhelpers.py", line 72, in __exit__
    with_traceback=exc_tb,
  File "/home/airflow/.local/lib/python3.7/site-packages/sqlalchemy/util/compat.py", line 211, in raise_
    raise exception
  File "/home/airflow/.local/lib/python3.7/site-packages/sqlalchemy/pool/base.py", line 686, in __connect
    self.dbapi_connection = connection = pool._invoke_creator(self)
  File "/home/airflow/.local/lib/python3.7/site-packages/sqlalchemy/engine/create.py", line 574, in connect
    return dialect.connect(*cargs, **cparams)
  File "/home/airflow/.local/lib/python3.7/site-packages/sqlalchemy/engine/default.py", line 598, in connect
    return self.dbapi.connect(*cargs, **cparams)
  File "/home/airflow/.local/lib/python3.7/site-packages/psycopg2/__init__.py", line 122, in connect
    conn = _connect(dsn, connection_factory=connection_factory, **kwasync)
sqlalchemy.exc.OperationalError: (psycopg2.OperationalError) could not translate host name "postgres" to address: Temporary failure in name resolution

(Background on this error at: https://sqlalche.me/e/14/e3q8)
[2023-07-18T00:09:33.606+0000] {local_task_job_runner.py:115} ERROR - Received SIGTERM. Terminating subprocesses
[2023-07-18T00:09:33.853+0000] {process_utils.py:135} INFO - Sending Signals.SIGTERM to group 692. PIDs of all processes in the group: [692]
[2023-07-18T00:09:33.867+0000] {process_utils.py:86} INFO - Sending the signal Signals.SIGTERM to group 692
[2023-07-18T00:09:34.835+0000] {taskinstance.py:1517} ERROR - Received SIGTERM. Terminating subprocesses.
[2023-07-18T00:09:37.932+0000] {taskinstance.py:1824} ERROR - Task failed with exception
Traceback (most recent call last):
  File "/home/airflow/.local/lib/python3.7/site-packages/airflow/operators/python.py", line 181, in execute
    return_value = self.execute_callable()
  File "/home/airflow/.local/lib/python3.7/site-packages/airflow/operators/python.py", line 198, in execute_callable
    return self.python_callable(*self.op_args, **self.op_kwargs)
  File "/opt/airflow/dags/main_dag.py", line 326, in k_core_shell_figure
    plt.savefig("figures/k-core_sociopatterns.png", dpi=600)
  File "/home/airflow/.local/lib/python3.7/site-packages/matplotlib/pyplot.py", line 977, in savefig
    res = fig.savefig(*args, **kwargs)
  File "/home/airflow/.local/lib/python3.7/site-packages/matplotlib/figure.py", line 3058, in savefig
    self.canvas.print_figure(fname, **kwargs)
  File "/home/airflow/.local/lib/python3.7/site-packages/matplotlib/backend_bases.py", line 2325, in print_figure
    **kwargs)
  File "/home/airflow/.local/lib/python3.7/site-packages/matplotlib/backend_bases.py", line 1648, in wrapper
    return func(*args, **kwargs)
  File "/home/airflow/.local/lib/python3.7/site-packages/matplotlib/_api/deprecation.py", line 415, in wrapper
    return func(*inner_args, **inner_kwargs)
  File "/home/airflow/.local/lib/python3.7/site-packages/matplotlib/backends/backend_agg.py", line 543, in print_png
    dpi=self.figure.dpi, metadata=metadata, pil_kwargs=pil_kwargs)
  File "/home/airflow/.local/lib/python3.7/site-packages/matplotlib/image.py", line 1675, in imsave
    image.save(fname, **pil_kwargs)
  File "/home/airflow/.local/lib/python3.7/site-packages/PIL/Image.py", line 2395, in save
    self._ensure_mutable()
  File "/home/airflow/.local/lib/python3.7/site-packages/PIL/Image.py", line 610, in _ensure_mutable
    self._copy()
  File "/home/airflow/.local/lib/python3.7/site-packages/PIL/Image.py", line 604, in _copy
    self.im = self.im.copy()
  File "/home/airflow/.local/lib/python3.7/site-packages/airflow/models/taskinstance.py", line 1519, in signal_handler
    raise AirflowException("Task received SIGTERM signal")
airflow.exceptions.AirflowException: Task received SIGTERM signal
[2023-07-18T00:09:37.948+0000] {taskinstance.py:1350} INFO - Marking task as FAILED. dag_id=main_dag, task_id=make_figures.plot_k_core_shell, execution_date=20230717T235106, start_date=20230718T000144, end_date=20230718T000937
[2023-07-18T00:09:37.994+0000] {standard_task_runner.py:109} ERROR - Failed to execute job 894 for task make_figures.plot_k_core_shell (Task received SIGTERM signal; 692)
[2023-07-18T00:09:38.027+0000] {local_task_job_runner.py:115} ERROR - Received SIGTERM. Terminating subprocesses
