[2023-07-16T15:12:31.984+0000] {taskinstance.py:1103} INFO - Dependencies all met for dep_context=non-requeueable deps ti=<TaskInstance: main_dag.make_figures.plot_all_together manual__2023-07-16T15:12:14.142676+00:00 [queued]>
[2023-07-16T15:12:31.998+0000] {taskinstance.py:1103} INFO - Dependencies all met for dep_context=requeueable deps ti=<TaskInstance: main_dag.make_figures.plot_all_together manual__2023-07-16T15:12:14.142676+00:00 [queued]>
[2023-07-16T15:12:31.998+0000] {taskinstance.py:1308} INFO - Starting attempt 1 of 1
[2023-07-16T15:12:32.017+0000] {taskinstance.py:1327} INFO - Executing <Task(PythonOperator): make_figures.plot_all_together> on 2023-07-16 15:12:14.142676+00:00
[2023-07-16T15:12:32.024+0000] {standard_task_runner.py:57} INFO - Started process 724 to run task
[2023-07-16T15:12:32.028+0000] {standard_task_runner.py:84} INFO - Running: ['***', 'tasks', 'run', 'main_dag', 'make_figures.plot_all_together', 'manual__2023-07-16T15:12:14.142676+00:00', '--job-id', '534', '--raw', '--subdir', 'DAGS_FOLDER/main_dag.py', '--cfg-path', '/tmp/tmpr5k7n35j']
[2023-07-16T15:12:32.033+0000] {standard_task_runner.py:85} INFO - Job 534: Subtask make_figures.plot_all_together
[2023-07-16T15:12:32.095+0000] {task_command.py:410} INFO - Running <TaskInstance: main_dag.make_figures.plot_all_together manual__2023-07-16T15:12:14.142676+00:00 [running]> on host 1696d5f40b5e
[2023-07-16T15:12:32.209+0000] {taskinstance.py:1547} INFO - Exporting env vars: AIRFLOW_CTX_DAG_OWNER='***' AIRFLOW_CTX_DAG_ID='main_dag' AIRFLOW_CTX_TASK_ID='make_figures.plot_all_together' AIRFLOW_CTX_EXECUTION_DATE='2023-07-16T15:12:14.142676+00:00' AIRFLOW_CTX_TRY_NUMBER='1' AIRFLOW_CTX_DAG_RUN_ID='manual__2023-07-16T15:12:14.142676+00:00'
[2023-07-16T15:16:17.749+0000] {taskinstance.py:1824} ERROR - Task failed with exception
Traceback (most recent call last):
  File "/home/airflow/.local/lib/python3.7/site-packages/airflow/operators/python.py", line 181, in execute
    return_value = self.execute_callable()
  File "/home/airflow/.local/lib/python3.7/site-packages/airflow/operators/python.py", line 198, in execute_callable
    return self.python_callable(*self.op_args, **self.op_kwargs)
  File "/opt/airflow/dags/main_dag.py", line 69, in all_together
    nodes = nx.draw_networkx_nodes(graph, pos=pos, node_color=color_degree, cmap=plt.cm.jet, vmin=0, vmax=max_centrality*0.002, ax=ax[0, 0])
NameError: name 'color_degree' is not defined
[2023-07-16T15:16:17.758+0000] {taskinstance.py:1350} INFO - Marking task as FAILED. dag_id=main_dag, task_id=make_figures.plot_all_together, execution_date=20230716T151214, start_date=20230716T151231, end_date=20230716T151617
[2023-07-16T15:16:17.771+0000] {standard_task_runner.py:109} ERROR - Failed to execute job 534 for task make_figures.plot_all_together (name 'color_degree' is not defined; 724)
[2023-07-16T15:16:17.815+0000] {local_task_job_runner.py:225} INFO - Task exited with return code 1
[2023-07-16T15:16:17.835+0000] {taskinstance.py:2653} INFO - 0 downstream tasks scheduled from follow-on schedule check
