[2023-07-17T08:40:28.607+0000] {taskinstance.py:1103} INFO - Dependencies all met for dep_context=non-requeueable deps ti=<TaskInstance: main_dag.preprocessing.data_acquisition manual__2023-07-17T08:39:40.566871+00:00 [queued]>
[2023-07-17T08:40:28.618+0000] {taskinstance.py:1103} INFO - Dependencies all met for dep_context=requeueable deps ti=<TaskInstance: main_dag.preprocessing.data_acquisition manual__2023-07-17T08:39:40.566871+00:00 [queued]>
[2023-07-17T08:40:28.618+0000] {taskinstance.py:1308} INFO - Starting attempt 1 of 1
[2023-07-17T08:40:28.633+0000] {taskinstance.py:1327} INFO - Executing <Task(PythonOperator): preprocessing.data_acquisition> on 2023-07-17 08:39:40.566871+00:00
[2023-07-17T08:40:28.638+0000] {standard_task_runner.py:57} INFO - Started process 4148 to run task
[2023-07-17T08:40:28.641+0000] {standard_task_runner.py:84} INFO - Running: ['***', 'tasks', 'run', 'main_dag', 'preprocessing.data_acquisition', 'manual__2023-07-17T08:39:40.566871+00:00', '--job-id', '634', '--raw', '--subdir', 'DAGS_FOLDER/main_dag.py', '--cfg-path', '/tmp/tmpvne7kxfc']
[2023-07-17T08:40:28.644+0000] {standard_task_runner.py:85} INFO - Job 634: Subtask preprocessing.data_acquisition
[2023-07-17T08:40:28.687+0000] {task_command.py:410} INFO - Running <TaskInstance: main_dag.preprocessing.data_acquisition manual__2023-07-17T08:39:40.566871+00:00 [running]> on host 0314a966ffa9
[2023-07-17T08:40:28.780+0000] {taskinstance.py:1547} INFO - Exporting env vars: AIRFLOW_CTX_DAG_OWNER='***' AIRFLOW_CTX_DAG_ID='main_dag' AIRFLOW_CTX_TASK_ID='preprocessing.data_acquisition' AIRFLOW_CTX_EXECUTION_DATE='2023-07-17T08:39:40.566871+00:00' AIRFLOW_CTX_TRY_NUMBER='1' AIRFLOW_CTX_DAG_RUN_ID='manual__2023-07-17T08:39:40.566871+00:00'
[2023-07-17T08:40:34.538+0000] {taskinstance.py:1824} ERROR - Task failed with exception
Traceback (most recent call last):
  File "/home/airflow/.local/lib/python3.7/site-packages/airflow/operators/python.py", line 181, in execute
    return_value = self.execute_callable()
  File "/home/airflow/.local/lib/python3.7/site-packages/airflow/operators/python.py", line 198, in execute_callable
    return self.python_callable(*self.op_args, **self.op_kwargs)
  File "/opt/airflow/dags/main_dag.py", line 89, in data_acquisition
    g.add_edge(page, link)
NameError: name 'g' is not defined
[2023-07-17T08:40:34.550+0000] {taskinstance.py:1350} INFO - Marking task as FAILED. dag_id=main_dag, task_id=preprocessing.data_acquisition, execution_date=20230717T083940, start_date=20230717T084028, end_date=20230717T084034
[2023-07-17T08:40:34.577+0000] {standard_task_runner.py:109} ERROR - Failed to execute job 634 for task preprocessing.data_acquisition (name 'g' is not defined; 4148)
[2023-07-17T08:40:34.639+0000] {local_task_job_runner.py:225} INFO - Task exited with return code 1
[2023-07-17T08:40:34.664+0000] {taskinstance.py:2653} INFO - 0 downstream tasks scheduled from follow-on schedule check
