[2023-07-16T04:24:42.770+0000] {taskinstance.py:1103} INFO - Dependencies all met for dep_context=non-requeueable deps ti=<TaskInstance: main_dag.preprocess_data manual__2023-07-16T04:24:28.154922+00:00 [queued]>
[2023-07-16T04:24:42.779+0000] {taskinstance.py:1103} INFO - Dependencies all met for dep_context=requeueable deps ti=<TaskInstance: main_dag.preprocess_data manual__2023-07-16T04:24:28.154922+00:00 [queued]>
[2023-07-16T04:24:42.780+0000] {taskinstance.py:1308} INFO - Starting attempt 1 of 1
[2023-07-16T04:24:42.793+0000] {taskinstance.py:1327} INFO - Executing <Task(PythonOperator): preprocess_data> on 2023-07-16 04:24:28.154922+00:00
[2023-07-16T04:24:42.798+0000] {standard_task_runner.py:57} INFO - Started process 971 to run task
[2023-07-16T04:24:42.800+0000] {standard_task_runner.py:84} INFO - Running: ['***', 'tasks', 'run', 'main_dag', 'preprocess_data', 'manual__2023-07-16T04:24:28.154922+00:00', '--job-id', '478', '--raw', '--subdir', 'DAGS_FOLDER/main_dag.py', '--cfg-path', '/tmp/tmpi0hdkipa']
[2023-07-16T04:24:42.803+0000] {standard_task_runner.py:85} INFO - Job 478: Subtask preprocess_data
[2023-07-16T04:24:42.851+0000] {task_command.py:410} INFO - Running <TaskInstance: main_dag.preprocess_data manual__2023-07-16T04:24:28.154922+00:00 [running]> on host 85db40224008
[2023-07-16T04:24:42.957+0000] {taskinstance.py:1547} INFO - Exporting env vars: AIRFLOW_CTX_DAG_OWNER='***' AIRFLOW_CTX_DAG_ID='main_dag' AIRFLOW_CTX_TASK_ID='preprocess_data' AIRFLOW_CTX_EXECUTION_DATE='2023-07-16T04:24:28.154922+00:00' AIRFLOW_CTX_TRY_NUMBER='1' AIRFLOW_CTX_DAG_RUN_ID='manual__2023-07-16T04:24:28.154922+00:00'
[2023-07-16T04:24:43.010+0000] {taskinstance.py:1824} ERROR - Task failed with exception
Traceback (most recent call last):
  File "/home/airflow/.local/lib/python3.7/site-packages/airflow/operators/python.py", line 181, in execute
    return_value = self.execute_callable()
  File "/home/airflow/.local/lib/python3.7/site-packages/airflow/operators/python.py", line 198, in execute_callable
    return self.python_callable(*self.op_args, **self.op_kwargs)
  File "/opt/airflow/dags/main_dag.py", line 36, in preprocess_data
    graph = nx.read_edgelist(f"data/{kwargs['file_name']}.txt", create_using=nx.Graph(), nodetype=int)
KeyError: 'file_name'
[2023-07-16T04:24:43.017+0000] {taskinstance.py:1350} INFO - Marking task as FAILED. dag_id=main_dag, task_id=preprocess_data, execution_date=20230716T042428, start_date=20230716T042442, end_date=20230716T042443
[2023-07-16T04:24:43.028+0000] {standard_task_runner.py:109} ERROR - Failed to execute job 478 for task preprocess_data ('file_name'; 971)
[2023-07-16T04:24:43.052+0000] {local_task_job_runner.py:225} INFO - Task exited with return code 1
[2023-07-16T04:24:43.081+0000] {taskinstance.py:2653} INFO - 0 downstream tasks scheduled from follow-on schedule check
